Workbook
Name aut: #REF!
Name CamposSIS: README!$A$24:$B$131
Name ConR: #REF!
Name Cris: #REF!
Name DatosEspecies: 'BASE MAESTRA'!$B$7:$DU$208
Name DisContHab: #REF!
Name DisContSubp: #REF!
Name EB_PotLC_need_Assessment: #REF!
Name FragSev: #REF!
Name iws: 'BASE MAESTRA'!#REF!
Name orden: #REF!
Name Paula: #REF!
Name ref: #REF!
Name RL: #REF!
Name Sin: #REF!
Name SISdetails: 'SIS DETAILS'!$A$1:$I$8
Name solotipo: #REF!
Name Taxonomy: '[1]ConR +Tax'!$A$1:$M$318

Sheet README
A2: IUCN - SSC - GRUPO DE ESPECIALISTAS DE PLANTAS DE COLOMBIA INSTRUCCIONES PARA DILIGENCIAR ESTE ARCHIVO PARA EVALUACIONES DE LISTA ROJA DE PLANTAS A NIVEL NACIONAL
A4: AUTORAS DE ESTE ARCHIVO | B4: Cristina Lopez-Gallego & Paula A. Morales Morales Grupo de Especialistas de Plantas de Colombia Grupo EECO - Instituto de Biología, Universidad de Antioquia
A6: INSTRUCCIONES GENERALES | B6: "Para tener en cuenta ANTES de subir evaluaciones de especies a la plataforma "SIS connect": - Para subir información de las evaluaciones a la plataforma "SIS connect" se deben producir 14 archivos tipo .csv y compilarlos en una carpeta ".zip" Esta carpeta se sube en la plataforma SIS connect como un "working set", y desde allí automáticamente se crean archivos individuales para cada especie en la plataforma "SIS". Las evaluaciones se pueden revisar posterioremente en la plataforma "SIS", si es necesario. Para realizar todo el proceso, es necesitario contactar la Unidad de Lista Roja de la IUCN, para obtener UNA CUENTA que permite acceder (con el mismo usuario y contraseña) a las plataformas de "SIS" y "SIS connect". - ANTES de subir tu "working set" en la plataforma de "SIS connect" debes contactar al Grupo de Especialistas de Plantas de Colombia <ge.plantascolombia@gmail.com>, para coordinar la revisión de estas evaluaciones y contactar a la Unidad de Lista Roja de la IUCN para su publicación. - Es MUY IMPORTANTE establecer si las especies que se están evaluando en tu proyecto YA se han evaluado antes Y/O YA están publicadas en la plataforma web de la Lista Roja Global. También es importante determinar si existe en este momento algún otro Grupo de especialistas de la IUCN que esté realizando esas evaluaciones. Si algunas de la especies que estás evaluando ya han sido o están siendo evaluadas actualmente, se debe coordinar la situación con el Grupo de Especialistas de Plantas de Colombia y la Unidad de Lista Roja de la IUCN (para decidir unir las dos evaluaciones, reemplazar las evaluaciones viejas, u otra opción) ANTES de subir su información al "SIS connect".
B7: Procedimiento general para compilar la información para las evaluaciones: - En este archivo de excel, se usa la pestaña "BASE MAESTRA" para digitar toda la información que se obtenga para la evaluación de cada especie. La información para cada especie se consigna en difrentes campos (las columnas). El archivo tiene instrucciones detalladas de como llenar cada uno de los campos, por favor seguir esas instrucciones detalladamente (de lo contrario, podrían haber errores al subir la información a "SIS connect"). La información de cada especie está en filas, y en este archivo se puede diligenciar información para un máximo de 200 especies. Recomendamos hacer archivos de menos de 200 especies, para facilitar su ingreso a la plataforma "SIS connect". Si su proyecto tiene menos de 200 especies a evaluar, BORRE las fórmulas en las filas que no se necesitan en todas las pestañas para construir los archivos .csv - Algunos de los campos (columnas) se deben llenar con códigos y opciones específicas de la plataforma SIS connect. En las instrucciones para llenar ese campo están descritas las opciones que se pueden usar, pero en algunos casos no estan todas las opciones disponibles. Si se considera que se necesitan opciones adicionales, en las instrucciones del campo se referencia la página web de SIS connect en donde se pueden consultar. En esa página, puedes ir a la pestaña "OAuth" (pestaña amarilla arriba) y entrar con tu cuenta de google o facebook (si no tienes cuenta en el SIS de IUCN). - Este archivo de excel tiene además 14 pestañas (nombradas en minúscula) que corresponden a los archivos .csv requeridos para subir la información a la plataforma "SIS connect". Este archivo tiene fórmulas de excel (por favor no modificarlas) que permiten que a medida que la información se llena en la pestaña "BASE MAESTRA", esa misma información se va copiando en 12 de las 14 pestañas del libro de excel (todas menos la de "credits" & "references") - Las pestañas de "credits" & "references" se deben diligenciar de forma manual (ver instrucciones acá abajo). - Luego de que toda la información para la evaluación este ingresada en la BASE MAESTRA y en las 14 pestañas de los .csv, siga el procedimiento descrito acá abajo para obtener los 14 archivos .csv a subir a la plataforma "SIS connect". - Luego de subir su información al "SIS connect", la Unidad de Lista Roja de la IUCN lo contactará para confirmar que todo este bien. Con esta persona de contacto de IUCN se debe acordar como enviar los datos espaciales de ocurrencias y los mapas elaborados para la evaluaciones (y fotos si se desea).
A9: PROCEDIMIENTO PARA OBTENER LOS ARCHIVOS PARA EL SIS CONNECT | B9: Procedimiento para obtener los 14 archivos .csv necesarios para subir la información a través de "SIS Connect"
B10: 1. Llena por completo los campos de información para cada especie en la pestaña "BASE MAESTRA", según las instrucciones para cada campo. Esa información se va consigando automáticamente en las pestañas (las pestañas despues de la pestaña "BASE MAESTRA") que serán la base para crear los archivos .csv para el "SIS connect" (excepto en las pestañas de "credits" y "references", que deben ser diligenciadas de manera manual, ver instrucciones más abajo).
B11: 2. Para crear los archivos .csv a partir de las pestañas correspondientes, debes hacer algunas modificaciones ANTES de guardarlos como .csv. Primero, para cada una de las pestañas de .csv, copia y pega (opción de pegar "sólo valores") la información de CADA pestaña en un nuevo archivo de excel (que tenga el nombre de la pestaña) por separado. En cada uno de los nuevos archivos (14 en total), realiza las siguientes modificaciones: - Borra la COLUMNA A & FILA 2 (que estan en fondo cafecito y con letra roja en el archivo original), esta información en letra roja NO debe estar en el .csv final a subir al SIS connect. - Borra las filas que NO se usaron para evaluaciones de especies (si es que había menos de 200 especies con información en la pestaña "BASE MAESTRA"). - Borra el contenido de las celdas que tengan valores de N/A para que queden como celdas vacías (esas son las celdas para los que no había información original en la pestaña de la "BASE MAESTRA"), con la función buscar y reemplazar de excel.
B12: 3. Hay algunos archivos de las pestañas que requieren de trabajo adicional antes de subirlos al "SIS connect". Por favor sigue estas instrucciones detalladamente para la pestaña de "synonims" y para las siguientes pestañas con códigos del SIS: "conservationneeded", "countries", "habitats", "plantspecific", "researchneeded", "threats", "usetrade" --> En estas pestañas, hay algunos campos (columnas en la "BASE MAESTRA") que pueden tener varias opciones (separadas por comas) para una misma especie. Estas son las Columnas N (sinónimos), U (códigos usos), Y (códigos hábitos), AB (códigos países), AM (códigos hábitats), BN (códigos amenazas), CB & CC (códigos conservación & investigación requeridas). --> Para estas pestañas, luego de grabar el archivo nuevo de excel correspondiente, se debe realizar el siguiente procedimiento: En el archivo DEBE HABER UNA SÓLA FILA para cada una de las opciones del campo de opciones múltiples para una especie. Si para una especie hay opciones múltiples en alguno de los campos referenciados arriba, se debe dejar sólo una opción en la primera fila, y se deben insertar nuevas filas en el archivo, para que cada fila contenga una opción diferente para la especie (sin comas). TODAS las filas que correspondan a opciones de la misma especie DEBEN tener el mismo número único identificador de la especie ("internal_taxon-id"). Así, para las especies que tenían múltiples opciones en los campos que lo permiten (sinónimos, amenazas, etc), quedáran múltiples filas, tantas filas como opciones tenía la especie en la base de datos original (pestaña "BASE MAESTRA"). --> Finalmente, diligencia las pestañas de "credits" & "references" según las instrucciones acá abajo.
B13: 4. Cuando todos los archivos correspondientes a las 14 pestañas para el "SIS connect" estén listos, guarda cada archivo en formato .csv (separado por comas). Se DEBE usar el mismo nombre de la pestaña original para nombrar cada archivo .csv NO usar la opción .csv UTF8, esta opción genera conflictos de idioma en esta plataforma.
B14: 5. Crea una carpeta comprimida .zip con los 14 archivos .csv de tus evaluaciones. El nombre de esta carpeta lo elige el usuario, y debe ser un nombre corto y sencillo alusivo al grupo de especies evaluadas.
B15: 6. Ingresa a la plataforma web del "SIS Connect" y crea un "workingset". En este "working set" se carga la carpeta .zip con la información de las especies. Sigue en esa plataforma web todas las instrucciones…
A17: INSTRUCCIONES PARA MANEJO DE CRÉDITOS Pestaña "credits" | B17: - La pestaña "credits" se debe diligenciar manualmente. Para cada especie, se debe tener en cuenta cuántas personas participaron en la evaluación de esa especie (se pueden considerar a los Herbarios o instituciones que participen, pero se recomienda considerar a todos los Herbarios como UNA SOLA "institución contribuyente"). En esta pestaña "credits", cada especie debe tener un número de filas equivalente al número de personas que participaron en la evaluación. CADA FILA que corresponda a personas participantes en la evaluación, DEBE tener en mismo "internal_taxon_id", que es el número único que permite identificar a la especie en la pestaña "BASE MAESTRA". - Las filas que correspondan a las personas participantes de la evaluación se debe organizar de una manera específica. Se debe establecer un orden jerárquico ("order") de contribución de cada persona a la evaluación de la especie. Esta información se consiga en la Columna B ("order"). Este orden lo puede definir el equipo de trabajo del proyecto, según el grado de participación de cada persona en la evaluación. En este orden jerárquico: * Van primero los EVALUADORES (persona-s que hacen análisis de la información total y asignan la categoría de lista roja de la especie) * Van despúes los CONTRIBUYENTES (persona-s o instuciones que contribuyen con infromación de base, georreferenciación, análisis de datos, revisión de información, etc.) * Van de último los REVISORES (persona-s que revisan la evaluación de lista roja una vez a sido finalizada) - Luego de llenar la información alusiva a las personas que particiaron en la evaluación de cada especie en esta pestaña, procede a copiar y pegar la información en otra hoja de excel con la opción de "pegar solo valores", borre la Columna A y las Filas 2 a la 6 con las instrucciones de llenado y el ejemplo (filas y columnas en beige y con texto rojo). Guarde el archivo en formato .csv nombrandolo con la palabra "credits".
B18: Recomendaciones importantes para diligenciar la Pestaña "credits" - El número de filas por especie (Internal Taxon ID) debe ser igual al número de personas involucradas en la evaluación de esa especie. - Cada persona involucrada en la evaluación de una especie debe tener un NÚMERO ÚNICO asignado en la jerarquía ("order") de participación. Si dos o más personas tienen participación equivalente en la evaluación, se debe definir un orden, no pueden tener el mismo número en la jerarquía. - Si en la evaluación de alguna especie alguna función del orden jerárquico preestablecido no está cubierta por alguna persona, se obvia y se continua la numeración. - No se acepta incluir más de un email por persona. - Está bien si los créditos son idénticos para todas las especies, en cuyo caso sólo sería cuestión de diligenciar las filas de información para la primera especie y luego copiar esas filas cuantas veces sea necesario (según el número de especies evaluadas).
A20: INSTRUCCIONES PARA MANEJO DE REFERENCIAS Pestaña "references" | B20: - La pestaña "references" se debe diligenciar manualmente. Para cada especie, se debe tener en cuenta cuántos recursos bibliográficos se usaron en la evaluación. En los campos de la "BASE MAESTRA" por favor hacer las citacion lo mas simple posible (con autores y año sin comas ni puntos). En la pestaña "references", cada especie debe tener un número de filas equivalente al número de recursos bibliográficos usados en su evaluación. CADA FILA que corresponda a recurso bibliográfico usado, DEBE tener un "internal_taxon_id", que corresponde al número único que permite identificar a la especie en la pestaña "BASE MAESTRA", y así se puede identificar a cuál especie corresponde ese recurso bilbiográfico. - Luego de llenar la información alusiva a los recursos bibliográficos usados en la evaluación de cada especie en esta pestaña, procede a copiar y pegar la información en otra hoja de excel con la opción de "pegar solo valores", borre la Columna A y las Filas 2 a la 5 con las instrucciones y el ejemplo (filas y columnas en beige y con texto rojo). Guarde el archivo en formato .csv nombrandolo con la palabra "references".
B21: Recomendaciones importantes para diligenciar la Pestaña "references" - Trate de hacer las referencias bibliográficas lo más sencillas posibles, minimizando los signos de puntuación y los caracteres que sean raros en inglés (como tildes, etc.), evite el uso de puntos finales en cada campo. - Use Mayúsculas para cada palabra inicial en los títulos de las referencias, especialmente en las que son en inglés. - Si la referencia es en inglés use "and" antes del último autor, si es en español use "y", si es en portugués use "e", no use "&". - Todas las referencias deben contar con año de publicación, fecha de acceso, lugar de publicación, editorial (publisher) y tipo de publicación. - Revise que un mismo recurso bibliográfico NO esté ingresado de formas diferentes para diferentes especies. En caso de usar un mismo recurso bibliográfico para diferentes especies, solo debe variar el "internal_taxon_id" ó número único identificador de la especie entre las filas que correspondan a ese recurso.
A23: NO ELIMINE O MODIFIQUE LA INFORMACION A CONTINUACION Los códigos en las filas siguientes son usados para introducir de manera automática la información que se consigna en la pestaña "base maestra" a las pestañas correspondientes para luego crear los archivos .csv a subir a la plataforma "sis connect"
A24: Campo | B24: Numero de celda
A25: internal_taxon_id | B25: 1
A26: kingdom | B26: 2
A27: phylum | B27: 3
A28: classname | B28: 4
A29: ordername | B29: 5
A30: family | B30: 6
A31: genus | B31: 7
A32: species | B32: 8
A33: taxonomicAuthority | B33: 9
A34: GEPC | B34: 10
A35: GEPC | B35: 11
A36: GEPC | B36: 12
... A67: GEPC | B67: 43
B68: 44
A69: GEPC | B69: 45
A70: EOO.range | B70: 46
A71: AOO.range | B71: 47
A72: SubpopulationNumber.range | B72: 48
A73: LocationsNumber.range | B73: 49
A74: GEPC | B74: 50
A75: GEPC | B75: 51
A76: GEPC | B76: 52
A77: GEPC | B77: 53
...

Sheet SIS DETAILS
A1: Data Point | B1: unit | C1: Tab | D1: Data Point | E1: Description | F1: Data Type | G1: File | H1: ClassificationType | I1: Needed in Import
A2: Need this for all the files to link together to the taxonomy | C2: Internal Taxon ID | D2: Need this for all the files to link together to the taxonomy
A3: internal_taxon_id | D3: internal_taxon_id | E3: should be unique - hopefully the external system will have one - IS REQUIRED | F3: Short text | G3: allfields.csv | I3: YES
A4: internal_taxon_id | D4: internal_taxon_id | E4: should be unique - hopefully the external system will have one - IS REQUIRED | F4: Short text | G4: assessments.csv | I4: YES
A5: internal_taxon_id | D5: internal_taxon_id | E5: should be unique - hopefully the external system will have one - IS REQUIRED | F5: Short text | G5: commonnames.csv | I5: YES
A6: internal_taxon_id | D6: internal_taxon_id | E6: should be unique - hopefully the external system will have one - IS REQUIRED | F6: Short text | G6: conservationneeded.csv | I6: YES
A7: internal_taxon_id | D7: internal_taxon_id | E7: should be unique - hopefully the external system will have one - IS REQUIRED | F7: Short text | G7: researchneeded.csv | I7: YES
A8: internal_taxon_id | D8: internal_taxon_id | E8: should be unique - hopefully the external system will have one - IS REQUIRED | F8: Short text | G8: plantspecific.csv | I8: YES
A9: internal_taxon_id | D9: internal_taxon_id | E9: should be unique - hopefully the external system will have one - IS REQUIRED | F9: Short text | G9: countries.csv | I9: YES
A10: internal_taxon_id | D10: internal_taxon_id | E10: should be unique - hopefully the external system will have one - IS REQUIRED | F10: Short text | G10: credits.csv | I10: YES
A11: internal_taxon_id | D11: internal_taxon_id | E11: should be unique - hopefully the external system will have one - IS REQUIRED | F11: Short text | G11: habitats.csv | I11: YES
A12: internal_taxon_id | D12: internal_taxon_id | E12: should be unique - hopefully the external system will have one - IS REQUIRED | F12: Short text | G12: references.csv | I12: YES
A13: internal_taxon_id | D13: internal_taxon_id | E13: should be unique - hopefully the external system will have one - IS REQUIRED | F13: Short text | G13: synonyms.csv | I13: YES
A14: internal_taxon_id | D14: internal_taxon_id | E14: should be unique - hopefully the external system will have one - IS REQUIRED | F14: Short text | G14: taxonomy.csv | I14: YES
... A18: internal_taxon_id | D18: internal_taxon_id | E18: should be unique - hopefully the external system will have one - IS REQUIRED | F18: Short text | G18: usetrade.csv | I18: YES
B19: Distribution
C20: Geographic Range
A21: RangeDocumentation.narrative | D21: RangeDocumentation.narrative | E21: Geographic Range Information. This is required for all the assessments apart from Least Concern (LC) | F21: Long Text/Narrative | G21: assessments.csv | I21: YES
C22: AOO
A23: AOO.range | D23: AOO.range | E23: Estimated area of occupancy (AOO) – in km2 | F23: Range | G23: allfields.csv
A24: AOO.justification | D24: AOO.justification | E24: Justification | F24: Short Text | G24: allfields.csv
A25: AOODetails.breedingRange | D25: AOODetails.breedingRange | E25: Range of breeding area (AOO) | F25: Range | G25: allfields.csv
A26: AOODetails.breedingRangeJustification | D26: AOODetails.breedingRangeJustification | E26: Justification of breeding area (AOO) | F26: Short Text | G26: allfields.csv
A27: AOODetails.nonbreedingRange | D27: AOODetails.nonbreedingRange | E27: Range of non-breeding area (AOO) | F27: Range | G27: allfields.csv
A28: AOODetails.nonbreedingRangeJustification | D28: AOODetails.nonbreedingRangeJustification | E28: Justification of non-breeding area (AOO) | F28: Short Text | G28: allfields.csv
A29: AOOContinuingDecline.isInContinuingDecline | D29: AOOContinuingDecline.isInContinuingDecline | E29: Continuing decline in area of occupancy (AOO). This field can take the following values: "1" (meaning true), "0" (meaning false), or "U" (meaning “unknown”) | F29: Boolean Range | G29: allfields.csv
A30: AOOContinuingDecline.qualifier | D30: AOOContinuingDecline.qualifier | E30: Qualifier | F30: Single Select | G30: allfields.csv
A31: AOOContinuingDecline.justification | D31: AOOContinuingDecline.justification | E31: Justification | F31: Short Text | G31: allfields.csv
A32: AOOExtremeFluctuation.isFluctuating | D32: AOOExtremeFluctuation.isFluctuating | E32: Extreme fluctuations in area of occupancy (AOO). This field can take the following values: "1" (meaning true), "0" (meaning false), or "U" (meaning “unknown”) | F32: Boolean Range | G32: allfields.csv
A33: AOOExtremeFluctuation.justification | D33: AOOExtremeFluctuation.justification | E33: Justification | F33: Short Text | G33: allfields.csv
C34: EOO
A35: EOO.range | D35: EOO.range | E35: Estimated extent of occurrence (EOO)- in km2 | F35: Range | G35: allfields.csv
A36: EOO.justification | D36: EOO.justification | E36: Justification | F36: Short Text | G36: allfields.csv
A37: EOOContinuingDecline.isContinuingDecline | D37: EOOContinuingDecline.isContinuingDecline | E37: Continuing decline in extent of occurrence (EOO). This field can take the following values: "1" (meaning true), "0" (meaning false), or "U" (meaning “unknown”) | F37: Boolean Range | G37: allfields.csv
A38: EOOContinuingDecline.qualifier | D38: EOOContinuingDecline.qualifier | E38: Qualifier | F38: Single Select | G38: allfields.csv
A39: EOOContinuingDecline.justification | D39: EOOContinuingDecline.justification | E39: Justification | F39: Short Text | G39: allfields.csv
A40: EOOExtremeFluctuation.isFluctuating | D40: EOOExtremeFluctuation.isFluctuating | E40: Extreme fluctuations in extent of occurrence (EOO). This field can take the following values: "1" (meaning true), "0" (meaning false), or "U" (meaning “unknown”) | F40: Boolean Range | G40: allfields.csv
A41: EOOExtremeFluctuation.justification | D41: EOOExtremeFluctuation.justification | E41: Justification | F41: Short Text | G41: allfields.csv
A42: EOODetails.breedingRange | D42: EOODetails.breedingRange | E42: Estimated extent of occurrence (EOO) for the breeding range- in km2 (relevant to breeding species) | F42: Range | G42: allfields.csv
A43: EOODetails.nonbreedingRange | D43: EOODetails.nonbreedingRange | E43: Estimated extent of occurrence (EOO) for the non-breeding range- in km2 | F43: Range | G43: allfields.csv
...

Sheet BASE MAESTRA
A1: Encargad@ | B1: Número interno del taxón "internal_taxon_id" | C1: REINO | D1: PHYLLUM | E1: CLASE | F1: ORDEN | G1: FAMILIA | H1: GÉNERO | I1: ESPECIE | J1: AUTOR | K1: NOMBRE CIENTÍFICO sin autor | L1: REFERENCIA DEL TIPO | M1: LISTA DE SINÓNIMOS con autor | N1: GÉNERO DE SINÓNIMOS | O1: EPÍTETO DE SINONIMOS | P1: AUTORES DE SINÓNIMOS | Q1: NOMBRE COMÚN PRINCIPAL | R1: CÓDIGO SIS LENGUAJE DEL NOMBRE COMÚN PRINCIPAL | S1: REPORTE DE NOMBRE COMÚN PRINCIPAL SIS | T1: CÓDIGO SIS USOS | U1: REPORTE DE NO USO SIS | V1: DESCRIPCIÓN DE USOS Y COMERCIO | W1: REPORTE USO INDIRECTO SIS | X1: CÓDIGOS SIS HÁBITO | Y1: CÓDIGO SIS HABITO TEXTO | Z1: DESCRIPCIÓN MORFOLÓGICA | AA1: CÓDIGO SIS PAÍS | AB1: CÓDIGO SIS PAÍS TEXTO | AC1: CÓDIGO SIS ORIGEN | AD1: CÓDIGO SIS PRESENCIA | AE1: LÍMITE INFERIOR RANGO ALTITUDINAL | AF1: LÍMITE SUPERIOR RANGO ALTITUDINAL | AG1: CÓDIGO SIS REGIÓN BIOGEOGRÁFICA | AH1: DESCRIPCIÓN DISTRIBUCIÓN GEOGRÁFICA | AI1: CÓDIGO SIS MAPA | AJ1: CÓDIGO SIS TERRESTRE O ACUÁTICA | AK1: CÓDIGO SIS CALIDAD DEL HÁBITAT | AL1: CÓDIGO SIS TIPO DE HÁBITAT | AM1: DESCRIPCIÓN HÁBITAT GENERAL | AN1: DESCRIPCIÓN ECOLOGÍA GENERAL | AO1: RESUMEN HABITAT Y ECOLOGÍA | AP1: TIPO DISPERSION | AQ1: OBSERVACIONES A DISPERSIÓN | AR1: DISTANCIA MÁXIMA DE DISPERSIÓN | AS1: UMBRAL PARCHE PEQUEÑO | AT1: NOMBRE CIENTÍFICO sin autor | AU1: EOO (S RedList) | AV1: AOO (S RedList) | AW1: EOO (km2) | AX1: AOO (km2) | AY1: # SUBPOBLACIONES | AZ1: # LOCALIDADES "locations" | BA1: % OCURRENCIAS EN AREAS PROTEGIDAS | BB1: % PARCHES PEQUEÑOS Y AISLADOS | BC1: % HUELLA HUMANA EN LA AOO | BD1: REPORTE SUBPOBLACIONES DESAPARECIDAS | BE1: CÓDIGO SIS FRAGMENTACIÓN | BF1: DESCRIPCIÓN DE FRAGMENTACIÓN SIS | BG1: CÓDIGO SIS DISMINUCIÓN CONTINUA HÁBITAT | BH1: DESCRIPCIÓN DE DISMINUCIÓN CONTINUA HÁBITAT SIS | BI1: CÓDIGO SIS FUENTE DE LA DISM. CONTINUA HÁBITAT | BJ1: CÓDIGO SIS DISMINUCIÓN CONTINUA SUBPOBLACIONES | BK1: DESCRIPCIÓN DE DISMINUCIÓN CONTINUA SUBPOBLACIONES SIS | BL1: CÓDIGO SIS FUENTE DE LA DISM. CONTINUA SUBPOBLACIONES | BM1: DESCRIPCIÓN TAMAÑO POBLACIONAL Y DEMOGRAFÍA | BN1: DESCRIPCIÓN AMENAZAS | BO1: CÓDIGO SIS AMENAZAS | BP1: CÓDIGO SIS TIEMPO DE LAS AMENAZAS | BQ1: CÓDIGO SIS ALCANCE DE LAS AMENAZAS | BR1: CÓDIGO SIS SEVERIDAD DE LAS AMENAZAS | BS1: CÓDIGO SIS PRESIONES RESULTADO DE AMENAZAS | BT1: REPORTE DE "NO AMENAZAS" SIS | BU1: REPORTE DE "AMENAZAS DESCONOCIDAS" SIS | BV1: CÓDIGO SIS TENDENCIA POBLACIONAL | BW1: CÓDIGO SIS FUENTE DE LA TENDENCIA POBLACIONAL | BX1: DESCRIPCIÓN ACCIONES DE CONSERVACIÓN | BY1: REPORTE DE PRESENCIA EN AREAS PROTEGIDAS | BZ1: LISTADO DE AREAS PROTEGIDAS CON OCURRENCIAS | CA1: REPORTE DE CONSERVACION EXSITU | CB1: LISTADO DE COLECCIONES EXSITU CON INDIVIDUOS | CC1: CÓDIGO SIS CONSERVACIÓN REQUERIDA | CD1: CÓDIGO SIS INVESTIGACION REQUERIDA | CE1: CÓDIGO SIS CATEGORÍA LISTA ROJA | CF1: LISTA DE CRITERIOS Y SUBCRITERIOS SIS | CG1: REPORTE DE CRITERIOS ingreso manual | CH1: REPORTE DE VERSIÓN DE CRITERIOS | CI1: REPORTE RAZÓN CATEGORIA DD | CJ1: REPORTE CATEGORIA EX | CK1: DESCRIPICIÓN JUSTIFICACION EVALUACIÓN DE LISTA ROJA | CL1: FECHA DE EVALUACIÓN | CM1: CÓDIGO SIS LENGUAJE DE LA EVALUACIÓN | CN1: REPORTE DE EVALUACIONES PREVIAS | CO1: JUSTIFICACIONES DE EVALUACIONES PREVIAS | CP1: REPORTE EVALUACIÓN PREVIA DE LR OFICIAL | CQ1: RAZONES DE CAMBIO DE CATEGORÍA | CR1: CÓDIGO SIS TIPO DE CAMBIO DE CATEGORÍA | CS1: CÓDIGO SIS NO CAMBIO DE CATEGORÍA | CT1: CÓDIGO SIS CAMBIOS GENUINOS Y NO-GENUINOS | CU1: LISTA DE CONTRIBUYENTES: PERSONAS | CV1: LISTA DE CONTRIBUYENTES: INSTITUCIONES | CW1: LISTA DE EVALUADORES | CX1: LISTA DE REVISORES | CY1: LISTA DE EXPERTOS TAXÓNOMOS | CZ1: COMENTARIOS DE LA REVISIÓN POR EXPERTOS | DA1: REFERENCIAS BIBLIOGRÁFICAS | DB1: OBSERVACIONES ADICIONALES
